Workbook
Name Instansi: [1]Pegawai!$B$54:$B$56
Name jabatan: '[2]master(jangan diubah)'!$M$1:$P$1
Name Jabatan1: [1]Pegawai!#REF!
Name Jabatan2: [1]Pegawai!#REF!
Name pegawai1: [1]Pegawai!$B$4:$B$43
Name penilai1: [1]Pegawai!$B$4:$B$4
Name terpenuhi: '[2]master(jangan diubah)'!$B$16:$B$17

Sheet DATA INDIVIDU
A1: DATA INDIVIDU PEGAWAI
A3: PEGAWAI YANG DINILAI
A4: NAMA | D4: : | E4: HENDRA POLJANDRY PUTUHENA | G4: PERHATIAN:
A5: NIP | D5: : | E5: 1.9690114e+17 | G5: 1. PANGKAT/GOLONGAN RUANG DIISI SEPERTI BIASA. Contoh: Penata Muda / (III/a)
A6: PANGKAT/GOL RUANG | D6: : | E6: III/d | G6: 2. Nama pegawai yang menilai dan yang dinilai akan secara otomatis tertulis pada sheet berikutnya. Akan tetapi harus ada checking berkala agar nama tidak salah
A7: JABATAN | D7: : | E7: KEPALA URUSAN TATA USAHA
A9: PEJABAT PENILAI KINERJA
A10: NAMA | D10: : | E10: PRIANGGORO AGUNG WIBOWO
A11: NIP | D11: : | E11: 1.9801229e+17
A12: PANGKAT/GOL RUANG | D12: : | E12: III/d
A13: JABATAN | D13: : | E13: KEPALA LEMBAGA PEMASYARAKATAN
A15: ATASAN PEJABAT PENILAI KINERJA
A16: NAMA | D16: : | E16: ACHMAD FAHRURAZI, S.H., M.H.
A17: NIP | D17: : | E17: 197812122001121001
A18: PANGKAT/GOL RUANG | D18: : | E18: Pembina (IV/a)
A19: JABATAN | D19: : | E19: Kepala Bagian Perencanaan dan Sistem Informasi Kepegawaian Biro Kepegawaian
A22: PERIODE PENILAIAN | D22: : | E22: 1 JANUARI S.D 31 DESEMBER 2026
A24: UNIT KERJA (atas) | D24: : | E24: LAPAS KELAS III SAUMLAKI
A25: UNIT KERJA (bawah) | D25: : | E25: LAPAS KELAS III SAUMLAKI
A27: TEMPAT TANDA TANGAN | D27: : | E27: X
A28: TANGGAL TANDA TANGAN | D28: : | E28: X

Sheet KUANTITATIF
A3: SASARAN KINERJA PEGAWAI
A4: PENDEKATAN HASIL KERJA KUANTITATIF
A5: BAGI PEJABAT PIMPINAN ADMINISTRASI DAN PEJABAT FUNGSIONAL
A7: KEMENTERIAN X | E7: PERIODE PENILAIAN: 1 JANUARI S.D. 31 DESEMBER TAHUN 2026
A8: PEGAWAI YANG DINILAI | E8: PEJABAT PENILAI KINERJA
A9: NAMA | C9: ='DATA INDIVIDU'!E4 -> HENDRA POLJANDRY PUTUHENA | E9: NAMA | F9: ='DATA INDIVIDU'!E10 -> PRIANGGORO AGUNG WIBOWO
A10: NIP | C10: ='DATA INDIVIDU'!E5 -> 1.9690114e+17 | E10: NIP | F10: ='DATA INDIVIDU'!E11 -> 1.9801229e+17 | I10: KETERANGAN:
A11: PANGKAT/GOL RUANG | C11: ='DATA INDIVIDU'!E6 -> III/d | E11: PANGKAT/GOL RUANG | F11: ='DATA INDIVIDU'!E12 -> III/d | I11: 1. RENCANA HASIL KINERJA PIMPINAN YANG DIINTERVENSI (2) diisi oleh butir SKP pimpinan yang menjadi penilai SKP anda. Contoh: pada bagian kepegawaian, kolom (2) diisi oleh butir SKP Kepala Sub Bagian Kepegawaian.
A12: JABATAN | C12: ='DATA INDIVIDU'!E7 -> KEPALA URUSAN TATA USAHA | E12: JABATAN | F12: ='DATA INDIVIDU'!E13 -> KEPALA LEMBAGA PEMASYARAKATAN | I12: 2. RENCANA HASIL KINERJA (3) diisi oleh butir SKP PEGAWAI YANG DINILAI. Contoh: pada bagian kepegawaian, kolom (2) diisi oleh staf kepegawaian yang nantinya akan dinilai kinerjanya oleh Kepala Sub Bagian Kepegawaian.
A13: UNIT KERJA | C13: ='DATA INDIVIDU'!E24 -> LAPAS KELAS III SAUMLAKI | E13: UNIT KERJA | F13: ='DATA INDIVIDU'!E25 -> LAPAS KELAS III SAUMLAKI | I13: 3. INDIKATOR KINERJA INDIVIDU (5) berisi output kegiatan dari butir SKP pegawai yang dinilai.
A14: HASIL KERJA | I14: 4. kolom (1), (2), (3), (4), (5) dan (6) pada tabel HASIL KINERJA AGAR DI COPY DAN DI PASTE KE SHEET-SHEET BERIKUTNYA SESUAI DENGAN KOLOM YANG BERLAKU.
A15: NO | B15: RENCANA HASIL KERJA PIMPINAN YANG DIINTERVENSI | D15: RENCANA HASIL KERJA | E15: ASPEK | F15: INDIKATOR KINERJA INDIVIDU | G15: TARGET
A16: (1) | B16: (2) | D16: (3) | E16: (4) | F16: (5) | G16: (6)
A17: A. KINERJA UTAMA
A18: 1 | B18: Meningkatnya Dukungan Layanan Manajemen Satker | D18: Tersusunnya dokumen pengelola BMN dan kerumahtangaan | E18: Kuantitas | F18: Jumlah dokumen pengelolaan BMN dan kerumahtanggan | G18: 20 Dokumen
E19: Kualitas | F19: Dokumen pengelolaan BMN dan kerumahtanggan tersusun ddngan baik | G19: 1
E20: waktu | F20: Ketepatan waktu pengelolaan dokumen BMN dan kerumahtanggan | G20: 12 Bulan
D21: Terpenuhinya data dan peningkatan kompetensi pegawai PAS | E21: Kuantitas | F21: Jumlah data peningkatan kompetensi pegawai | G21: 5 Dokumen
E22: Kualitas | F22: Data kompetensi pegawai yang akurat | G22: 1
E23: waktu | F23: Ketepatan waktu pengelolaan data | G23: 12 Bulan
D24: Tersusunnya dokumen pelaksanaan anggaran dan laporan keuangan yang akuntabel dan tepat waktu | E24: Kuantitas | F24: Jumlah dokumen pelaksanaan anggaran dan laporan keuangan | G24: 40 Dokumen
E25: Kualitas | F25: Dokumen pelaksanaan anggaran dan laporan keuangan disusun secara baik dan tepat | G25: 1
E26: waktu | F26: Ketepatan waktu penyusunan anggaran dan laporan | G26: 12 Bulan
D27: Tersusunnya dokumen renja, anggaran UPT PAS dan pelaporan yang akuntabel dan tepat waktu | E27: Kuantitas | F27: Jumlah dokumen rencana kerja, anggaran UPT dan pelaporan | G27: 36 Dokumen
E28: Kualitas | F28: Ketepatan penyelesaian dokumen rencana kerja, anggaran UPT dan Pelaporan secara baik dan akurat | G28: 1
E29: waktu | F29: Ketepatan waktu penyusunan dokumen rencana kerja,anggaran UPT dan Pelaporan | G29: 12 Bulan
D30: Tersedianya layanan perkantoran | E30: Kuantitas | F30: Tersedianya layanan perkantoran yang baik | G30: 150 kegiatan
E31: Kualitas | F31: Ketepatan pelayanan layanan perkantoran dengan baik | G31: 1
E32: waktu | F32: Ketepatan waktu penyelesaian | G32: 12 Bulan
A33: PERILAKU | B33: KERJA
A34: 1 | B34: Berorientasi Pelayanan
B35: - Memahami dan memenuhi kebutuhan masyarakat | E35: Ekspektasi Khusus Pimpinan : - Maksimal dalam pelayanan dan terbuka terhadap masukan dari rekan kerja atau pihak lain -Selalu belajar dari kesalahan untuk perbaikan kinerja selanjutnya
B36: - Ramah, cekatan, solutif, dan dapat diandalkan
B37: - Melakukan perbaikan tiada henti
A38: 2 | B38: Akuntabel
B39: - Melaksanakan tugas dengan jujur, bertanggungjawab, cermat, disiplin dan berintegritas tinggi | E39: Ekspektasi Khusus Pimpinan
B40: - Menggunakan kekayaan dan barang milik negara secara bertanggungjawab, efektif dan efisien | E40: - Berani bertugas terang jika merasa ada kesalahan dan mengakui keselahan yang telah dibuat.
B41: - Tidak menyalahgunakan kewenangan jabatan | E41: - Melakukan tugas sesuai dengan kewenangan jabatan yang diberikan
A42: 3 | B42: Kompeten
B43: - Meningkatkan kompetensi diri untuk untuk menjawab tanrtangan yang selalu berubah | E43: Ekspektasi Khusus Pimpinan:
...

Sheet LAMPIRAN SKP
A3: LAMPIRAN SASARAN KINERJA PEGAWAI
A5: KEMENTERIAN X | H5: PERIODE PELAYANAN
H6: …. BULAN TAHUN S.D ... BULAN TAHUN
A7: DUKUNGAN SUMBER DAYA | N7: Keterangan:
A8: 1. | B8: …... | N8: 1. poin dukungan sumber dyaa dapat diisi dan disesuaikan antara penggunaan laptop/PC
A9: SKEMA PERTANGGUNGJAWABAN | N9: 2. Poin 3 dapat disesuaikan dengan sub bagian masing-masing.
A10: 1 | B10: …..
A11: KONSEKUENSI
A12: 2. | B12: …..
H13: LOKASI .. BULAN TAHUN
A14: PNS yang dinilai, | H14: Pejabat Penilai,
A18: ='DATA INDIVIDU'!E4 -> HENDRA POLJANDRY PUTUHENA | H18: ='DATA INDIVIDU'!E10 -> PRIANGGORO AGUNG WIBOWO
A19: ='DATA INDIVIDU'!E5 -> 1.9690114e+17 | H19: =KUANTITATIF!F72 -> PRIANGGORO AGUNG WIBOWO

Sheet Sheet1
A1: MATRIKS PEBAGIAN PERAN DAN HASIL
A2: PERIODE TAHUN 2026
A4: PEGAWAI | B4: JABATAN | C4: OUTCOME ANTARA/OUTPUT/LAYANAN
A5: PRIANGGORO AGUNG WIBOWO, S.H.,M.H | B5: KEPALA LAPAS | C5: Meningkatnya Dukungan Layanan Manajemen Satker
A6: HENDRA P. PUTUHENA, S.H | B6: KEPALA URUSAN TATA USAHA | C6: Tersusunnya dokumen pengelolaan BMN dan kerumahtangaaan
C7: Terpenuhinya data dan peningkatan kompetensi pegawai PAS
C8: Tersusunnya dokumen pelaksanaan anggaran dan laporan keuangan yang akuntabel dan tepat waktu
C9: Tersusunnya dokumen renja, anggaran UPT PAS dan pelaporan yang akuntabel dan tepat waktu
C10: Tersedianya layanan perkantoran

Sheet Sheet2

Sheet UMPAN BALIK KUANTITATIF (I)
A3: REKAMAN INFORMASI UMPAN BALIK BERKELANJUTAN
A4: PENDEKATAN HASIL KERJA KUANTITATIF
A5: BAGI PEJABAT PIMPINAN ADMINISTRASI DAN PEJABAT FUNGSIONAL
A8: KEMENTERIAN X | G8: PERIODE PENILAIAN: .. BULAN S.D ... BULAN TAHUN
A9: PEGAWAI YANG DINILAI | F9: PEJABAT PENILAI KINERJA
A10: NAMA | C10: ='DATA INDIVIDU'!E4 -> HENDRA POLJANDRY PUTUHENA | F10: NAMA | H10: ='DATA INDIVIDU'!E10 -> PRIANGGORO AGUNG WIBOWO
A11: NIP | C11: ='DATA INDIVIDU'!E5 -> 1.9690114e+17 | F11: NIP | H11: ='DATA INDIVIDU'!E11 -> 1.9801229e+17
A12: PANGKAT/GOL RUANG | C12: ='DATA INDIVIDU'!E6 -> III/d | F12: PANGKAT/GOL RUANG | H12: ='DATA INDIVIDU'!E12 -> III/d
A13: JABATAN | C13: ='DATA INDIVIDU'!E7 -> KEPALA URUSAN TATA USAHA | F13: JABATAN | H13: ='DATA INDIVIDU'!E13 -> KEPALA LEMBAGA PEMASYARAKATAN
A14: UNIT KERJA | C14: ='DATA INDIVIDU'!E24 -> LAPAS KELAS III SAUMLAKI | F14: UNIT KERJA | H14: ='DATA INDIVIDU'!E25 -> LAPAS KELAS III SAUMLAKI
A15: HASIL KERJA
A16: NO | B16: RENCANA HASIL KERJA PIMPINAN YANG DIINTERVENSI | D16: RENCANA HASIL KERJA | E16: ASPEK | F16: INDIKATOR KINERJA INDIVIDU | G16: TARGET | H16: REALISASI BERDASARKAN BUKTI DUKUNG | I16: UMPAN BALIK BERKELANJUTAN BERDASARKAN BUKTI DUKUNG
A17: (1) | B17: (2) | D17: (3) | E17: (4) | F17: (5) | G17: (6) | H17: (7) | I17: (8)
A18: A. KINERJA UTAMA
A19: 1 | B19: X | D19: X | E19: kuantitas/kualitas/waktu/kecepatan penyelesaian hasil kerja/biaya | F19: X | G19: X | H19: X | I19: Dibawah/Sesuai/diatas ekspektasi | J19: PASTE, SESUAIKAN BANYAK KOLOM DENGAN SHEET KUALITATIF
D20: X | E20: kuantitas/kualitas/waktu/kecepatan penyelesaian hasil kerja/biaya | F20: X | G20: X | H20: X | I20: Dibawah/Sesuai/diatas ekspektasi
A21: 2 | B21: X | D21: X | E21: kuantitas/kualitas/waktu/kecepatan penyelesaian hasil kerja/biaya | F21: X | G21: X | H21: X | I21: Dibawah/Sesuai/diatas ekspektasi
D22: X | E22: kuantitas/kualitas/waktu/kecepatan penyelesaian hasil kerja/biaya | F22: X | G22: X | H22: X | I22: Dibawah/Sesuai/diatas ekspektasi
A23: B. KINERJA TAMBAHAN
A24: - | D24: - | G24: -
A26: PERILAKU KERJA | I26: UMPAN BALIK BERKELANJUTAN BERDASARKAN BUKTI DUKUNG
A27: 1 | B27: Berorientasi Pelayanan
B28: - Memahami dan memenuhi kebutuhan masyarakat | G28: Ekspektasi Khusus Pimpinan | I28: Sesuai Ekspektasi
B29: - Ramah, cekatan, solutif, dan dapat diandalkan
B30: - Melakukan perbaikan tiada henti
A31: 2 | B31: Akuntabel
B32: - Melaksanakan tugas dengan jujur, bertanggungjawab, cermat, disiplin dan berintegritas tinggi | G32: Ekspektasi Khusus Pimpinan | I32: =KUANTITATIF!E38 -> 0
B33: - Menggunakan kekayaan dan barang milik negara secara bertanggungjawab, efektif dan efisien
B34: - Tidak menyalahgunakan kewenangan jabatan
A35: 3 | B35: Kompeten
B36: - Meningkatkan kompetensi diri untuk untuk menjawab tantangan yang selalu berubah | G36: Ekspektasi Khusus Pimpinan | I36: Sesuai Ekspektasi
B37: - Membantu orang lain belajar
B38: - Melaksanakan tugas dengan kualitas terbaik
A39: 4 | B39: Harmonis
B40: - Menghargai setiap orang apapun latar belakangnya | G40: Ekspektasi Khusus Pimpinan | I40: Sesuai Ekspektasi
B41: - Suka menolong orang lain
B42: - Membangun lingkungan kerja yang kondusif
A43: 5 | B43: Loyal
B44: - Memegang teguh ideologi Pancasila, Undang-Undang Dasar Negara Republik Indonesia Tahun 1945, setia pada Negara Kesatuan Republik Indonesia serta pemerintahan yang sah | G44: Ekspektasi Khusus Pimpinan | I44: Sesuai Ekspektasi
B45: - Menjaga nama baik ASN, Pimpinan, Instansi dan Negara
...

Sheet EVALUASI KUANTITATIF (I)
A3: HASIL EVALUASI KINERJA PEGAWAI
A4: PENDEKATAN HASIL KERJA KUANTITATIF
A5: BAGI PEJABAT PIMPINAN TINGGI DAN PIMPINAN UNIT KERJA MANDIRI
A8: KEMENTERIAN X | F8: PERIODE PENILAIAN: .. BULAN S.D .. BULAN TAHUN
A9: PEGAWAI YANG DINILAI | E9: PEJABAT PENILAI KINERJA
A10: NAMA | C10: ='DATA INDIVIDU'!E4 -> HENDRA POLJANDRY PUTUHENA | E10: NAMA | G10: ='DATA INDIVIDU'!E10 -> PRIANGGORO AGUNG WIBOWO
A11: NIP | C11: ='DATA INDIVIDU'!E5 -> 1.9690114e+17 | E11: NIP | G11: ='DATA INDIVIDU'!E11 -> 1.9801229e+17
A12: PANGKAT/GOL RUANG | C12: ='DATA INDIVIDU'!E6 -> III/d | E12: PANGKAT/GOL RUANG | G12: ='DATA INDIVIDU'!E12 -> III/d
A13: JABATAN | C13: ='DATA INDIVIDU'!E7 -> KEPALA URUSAN TATA USAHA | E13: JABATAN | G13: ='DATA INDIVIDU'!E13 -> KEPALA LEMBAGA PEMASYARAKATAN
A14: UNIT KERJA | C14: X | E14: UNIT KERJA | G14: X
A15: CAPAIAN KINERJA ORGANISASI* (ISTIMEWA/BAIK/BUTUH PERBAIKAN/KURANG/SANGAT KURANG)
A16: POLA DISTRIBUSI: DIISI DENGAN KURVA PENILAIAN KINERJA ORGANISASI
A17: HASIL KERJA
A18: NO | B18: RENCANA HASIL KERJA PIMPINAN YANG DIINTERVENSI | D18: RENCANA HASIL KERJA | E18: ASPEK | F18: INDIKATOR KINERJA INDIVIDU | G18: TARGET | H18: REALISASI BERDASARKAN BUKTI DUKUNG | I18: UMPAN BALIK BERKELANJUTAN BERDASARKAN BUKTI DUKUNG
A19: (1) | B19: (2) | D19: (3) | E19: (4) | F19: (5) | G19: (6) | H19: (7) | I19: (8)
A20: A. KINERJA UTAMA
A21: 1 | B21: X | D21: X | E21: kuantitas/kualitas/waktu/kecepatan penyelesaian hasil kerja/biaya | F21: X | G21: X | H21: X | I21: Dibawah/Sesuai/diatas ekspektasi
D22: X | E22: kuantitas/kualitas/waktu/kecepatan penyelesaian hasil kerja/biaya | F22: X | G22: X | H22: X | I22: Dibawah/Sesuai/diatas ekspektasi
A23: 2 | B23: X | D23: X | E23: kuantitas/kualitas/waktu/kecepatan penyelesaian hasil kerja/biaya | F23: X | G23: X | H23: X | I23: Dibawah/Sesuai/diatas ekspektasi
D24: X | E24: kuantitas/kualitas/waktu/kecepatan penyelesaian hasil kerja/biaya | F24: X | G24: X | H24: X | I24: Dibawah/Sesuai/diatas ekspektasi
A25: B. KINERJA TAMBAHAN
A26: - | D26: - | E26: -
A28: RATING HASIL KERJA* (DIATAS EKSPEKTASI/ SESUAI EKSPEKTASI/ DIBAWAH EKSPEKTASI)**
A29: PERILAKU KERJA | H29: UMPAN BALIK BERKELANJUTAN BERDASARKAN BUKTI DUKUNG
A30: 1 | B30: Berorientasi Pelayanan
B31: - Memahami dan memenuhi kebutuhan masyarakat | E31: Ekspektasi Khusus Pimpinan | H31: Dibawah/Sesuai/diatas ekspektasi
B32: - Ramah, cekatan, solutif, dan dapat diandalkan
B33: - Melakukan perbaikan tiada henti
A34: 2 | B34: Akuntabel
B35: - Melaksanakan tugas dengan jujur, bertanggungjawab, cermat, disiplin dan berintegritas tinggi | E35: Ekspektasi Khusus Pimpinan | H35: Dibawah/Sesuai/diatas ekspektasi
B36: - Menggunakan kekayaan dan barang milik negara secara bertanggungjawab, efektif dan efisien
B37: - Tidak menyalahgunakan kewenangan jabatan
A38: 3 | B38: Kompeten
B39: - Meningkatkan kompetensi diri untuk untuk menjawab tanrtangan yang selalu berubah | E39: Ekspektasi Khusus Pimpinan | H39: Dibawah/Sesuai/diatas ekspektasi
B40: - Membantu orang lain belajar
B41: - Melaksanakan tugas dengan kualitas terbaik
A42: 4 | B42: Harmonis
B43: - Menghargai setiap orang apapun latar belakangnya | E43: Ekspektasi Khusus Pimpinan | H43: Dibawah/Sesuai/diatas ekspektasi
B44: - Suka menolong orang lain
B45: - Membangun lingkungan kerja yang kondusif
...

Sheet KURVAPENILAIANKINERJAORGANISASI
C14: BAIK | H14: ISTIMEWA | O14: BUTUH PERBAIKAN
F31: KURANG | O31: SANGAT KURANG

Sheet DOKUMEN EVALUASI
A2: DOKUMEN EVALUASI KINERJA PEGAWAI
A3: PERIODE: TAHUN 2026
D5: PERIODE PENILAIAN:
A6: LAPAS KELAS III SAUMLAKI | D6: 01 JANUARI SD 31 DESEMBER 2026
A8: 1. | B8: PEGAWAI YANG DINILAI
B9: NAMA | C9: : | D9: ='DATA INDIVIDU'!E4 -> HENDRA POLJANDRY PUTUHENA
B10: NIP | C10: : | D10: ='DATA INDIVIDU'!E5 -> 1.9690114e+17
B11: PANGKAT/GOL RUANG | C11: : | D11: ='DATA INDIVIDU'!E6 -> III/d
B12: JABATAN | C12: : | D12: ='DATA INDIVIDU'!E7 -> KEPALA URUSAN TATA USAHA
B13: UNIT KERJA | C13: : | D13: ='DATA INDIVIDU'!E24 -> LAPAS KELAS III SAUMLAKI
A14: 2. | B14: PEJABAT PENILAI KINERJA
B15: NAMA | C15: : | D15: PRIANGGORO AGUNG WIBOWO
B16: NIP | C16: : | D16: 1.9801229e+17
B17: PANGKAT/GOL RUANG | C17: :
B18: JABATAN | C18: : | D18: KEPALA LEMBAGA PEMASYARAKATAN
B19: UNIT KERJA | C19: : | D19: ='DATA INDIVIDU'!E25 -> LAPAS KELAS III SAUMLAKI
A20: 3. | B20: ATASAN PEJABAT PENILAI KINERJA
B21: NAMA | C21: : | D21: X
B22: NIP | C22: : | D22: X
B23: PANGKAT/GOL RUANG | C23: : | D23: X
B24: JABATAN | C24: : | D24: X
B25: UNIT KERJA | C25: : | D25: X
A26: 4. | B26: EVALUASI KINERJA
B27: CAPAIAN KINERJA ORGANISASI | C27: : | D27: ISTIMEWA/BAIK/BUTUH PERBAIKAN/KURANG/SANGAT KURANG
B28: PREDIKAT KINERJA PEGAWAI | C28: : | D28: SANGAT BAIK/BAIK/BUTUH PERBAIKAN/KURANG/SANGAT KURANG
A29: 5. | B29: CATATAN/REKOMENDASI
B32: LOKASI, .. BULAN TAHUN | D32: LOKASI, .. BULAN TAHUN
B33: Pegawai yang Dinilai | D33: Pejabat Penilai Kinerja
B38: ='DATA INDIVIDU'!E4 -> HENDRA POLJANDRY PUTUHENA | D38: ='DATA INDIVIDU'!E10 -> PRIANGGORO AGUNG WIBOWO
B39: ='DATA INDIVIDU'!E5 -> 1.9690114e+17 | D39: ='DATA INDIVIDU'!E11 -> 1.9801229e+17
